Workbook
Name OLE_LINK1: Papers_reports!$M$73

Sheet CGC_projects
A1: Client/Collaborator | B1: Topic | C1: RoleCGC | D1: Year_CGC
A2: RESPEC Earth Res | B2: AMD treatment | C2: Technical specialist, AMD (Schmidt) | D2: 2025-present
A3: Kleinfelder | B3: AMD/AML investigation | C3: Technical specialist, AMD (Clark) | D3: 2025-present
A4: TetraTech | B4: AMD/AML investigation | C4: Technical specialist, AMD (Cavazza) | D4: 2025-present
A5: Neomaterials | B5: Rare-earth elements | C5: Technical specialist, rare-earth modeling (Haneline) | D5: 2024-2025
A6: Schuylkill Conservation District | B6: AMD/AML investigation | C6: Technical specialist, AMD (Lehman) | D6: 2025-present
A7: Life Cycle Geo | B7: AMD/AML investigation | C7: Technical specialist, AMD (Meuzelaar) | D7: 2025
A8: U.S. Geological Survey EHM | B8: Critical minerals | C8: Technical specialist, critical minerals (White) | D8: 2024-present
A9: U.S. Geological Survey GW Predict | B9: Salinity of groundwater | C9: Technical specialist, salinity (Stackelberg) | D9: 2024-present
A10: Saint Francis Univ. | B10: Rare-earth elements | C10: Technical specialist, rare-earth modeling (Tasker) | D10: 2024-present
A11: Univ. Pittsburgh | B11: Groundwater geochemistry | C11: Graduate research adviser (Schaffer; Capo) | D11: 2024-2025
A12: Univ. Pittsburgh | B12: Rare-earth elements | C12: Graduate research adviser (Boothe-Lordon; Stewart) | D12: 2024-present
A13: Penn State Univ. | B13: Rare-earth elements | C13: Graduate research adviser (Neat; Macalady) | D13: 2024-present
A14: Dusquesne Univ. | B14: Rare-earth elements | C14: Graduate research adviser (Terra; Trun) | D14: 2024-present
A15: Villanova Univ. | B15: Salinity of surfacewater | C15: Graduate research adviser (Graham; Goldsmith) | D15: 2024-present
A16: West Virginia Univ. | B16: Rare-earth elements | C16: Graduate research adviser (Seifert; Vesper) | D16: 2024-present
A17: Univ. Minho, Portugal | B17: AMD characterization/treatment | C17: Graduate research adviser (Barroso; Valente) | D17: 2024-present
A18: Univ. Evora, Portugal | B18: AMD characterization/treatment | C18: Graduate research adviser (Araujo; Fonseca) | D18: 2024-present

Sheet CGC_news
A1: Date | B1: Keywords | C1: Title | D1: Authors_short | E1: Authors | F1: Publisher | G1: Link
A2: =Papers_reports!C2 -> 2026 | B2: Groundwater, TDS, salinity, major ions, monitoring | C2: =Papers_reports!D2 -> Random forest predictions of total dissolved solids in groundwater in three dimensions across the continental United States | D2: Knierim et al. | E2: =Papers_reports!B2 -> Knierim, K.J., Stackelberg, P.E., McCleskey, R.B., Cravotta, C.A. III, Belitz, K., Killian, C.D. | F2: =Papers_reports!E2 -> Water Resources Research, submitted | G2: =Papers_reports!F2 -> 0
A3: =Papers_reports!C3 -> 2026 | B3: Groundwater, TDS, salinity, major ions, monitoring | C3: =Papers_reports!D3 -> Predicting groundwater hydrochemical facies in three dimensions across the conterminous United States with random forest classification | D3: Stackelberg et al. | E3: =Papers_reports!B3 -> Stackelberg, P.E., Knierim, K.J., Belitz, K., Cravotta, C.A. III, McCleskey, R.B., Killian, C.D. | F3: =Papers_reports!E3 -> Groundwater, submitted | G3: =Papers_reports!F3 -> 0
A4: =Papers_reports!C4 -> 2026 | B4: AMD, rare earths, critical minerals, modeling | C4: =Papers_reports!D4 -> Geochemical modeling of rare earth element adsorption onto aluminum hydroxide and hydroxysulfate under variable sulfate conditions | D4: Boothe-Lordon et al. | E4: =Papers_reports!B4 -> Boothe-Lordon, T.J.Cravotta, C.A. III, Tasker, T.L., Stewart, B.W., Capo, R.C., Hedin, B. | F4: =Papers_reports!E4 -> Chemosphere, submitted | G4: =Papers_reports!F4 -> 0
A5: =Papers_reports!C5 -> 2026 | B5: AMD, rare earths, critical minerals, modeling | C5: =Papers_reports!D5 -> Sorption of rare-earth elements with hydrous ferric oxide and hydrous aluminum oxide--Roles of sulfate and pH | D5: Tasker et al. | E5: =Papers_reports!B5 -> Tasker, T.L., Cravotta, C.A. III, Roman, B. | F5: =Papers_reports!E5 -> Chemosphere, submitted | G5: =Papers_reports!F5 -> http://dx.doi.org/10.2139/ssrn.6208107
A6: =Papers_reports!C6 -> 2026 | B6: AMD, human wastewater, nutrients, metals, cotreatment | C6: =Papers_reports!D6 -> Enhanced phosphorus removal via cotreatment of mine drainage during primary municipal wastewater clarification | D6: Roman et al. | E6: =Papers_reports!B6 -> Roman, B., Cravotta, C.A. III, Spellman Jr., C.J., Strosnider, W.H.J., Goodwill, J.E., Tasker, T.L. | F6: =Papers_reports!E6 -> Ecological Engineering 98 (2) e70298 | G6: =Papers_reports!F6 -> https://doi.org/10.1002/wer.70298
A7: =Papers_reports!C7 -> 2026 | B7: Groundwater, TDS, salinity, major ions, monitoring | C7: =Papers_reports!D7 -> Groundwater salinity: Applying the specific conductance and water type proxy | D7: McCleskey et al. | E7: =Papers_reports!B7 -> McCleskey, B.R., Cravotta, C.A. III, Knierim, K., Stackelberg, P.E., Killian, C. | F7: =Papers_reports!E7 -> Groundwater 64 (2) 150-160 | G7: =Papers_reports!F7 -> https://doi.org/10.1111/gwat.70038
A8: =Papers_reports!C8 -> 2025 | B8: AMD, Chesapeake Bay, nutrients, metals | C8: =Papers_reports!D8 -> Nutrient reductions as co-benefit of acid mine drainage (AMD) treatment: Quantifying nutrient load reductions for restored stream segments in AMD-impacted watersheds | D8: Hayes et al. | E8: =Papers_reports!B8 -> Hayes, B., Zhu, W., Dawes, R.J., Cravotta, C.A., Hughes, R., Moyer, G., Tasker, T., Shallenberger, J., Dawes, J. | F8: =Papers_reports!E8 -> Chesapeake Bay Program Scientific and Technical Advisory Committee (STAC) Publication Number 25-002, 44 p. | G8: =Papers_reports!F8 -> https://www.chesapeake.org/stac/wp-content/uploads/2025/04/STAC-Technical-Review_Acid-Mine-Drainage_25-002.pdf
A9: =Papers_reports!C9 -> 2025 | B9: Streamwater, TDS, salinity, major ions, monitoring | C9: =Papers_reports!D9 -> Specific conductance and water type as a proxy model for salinity and total dissolved solids measurements in the Upper Colorado River Basin | D9: McCleskey et al. | E9: =Papers_reports!B9 -> McCleskey, R.B., Cravotta, C.A. III, Miller, M.P., Chapin, T.W., Tillman, F., Keith, G.L. | F9: =Papers_reports!E9 -> Applied Geochemistry 184, 106358. | G9: =Papers_reports!F9 -> https://doi.org/10.1016/j.apgeochem.2025.106358
A10: =Papers_reports!C10 -> 2025 | B10: AMD, CO2 measurement, modeling | C10: =Papers_reports!D10 -> Determination of CO2 and DIC in high-CO2 waters: An application for the analysis of coal mine waters | D10: Vesper et al. | E10: =Papers_reports!B10 -> Vesper, D.J., Cravotta, C.A. III, Lei, L., Wallace, M., Schaffer, C.R. | F10: =Papers_reports!E10 -> Applied Geochemistry 183, 106336. | G10: =Papers_reports!F10 -> https://doi.org/10.1016/j.apgeochem.2025.106336
A11: =Papers_reports!C11 -> 2025 | B11: AMD, metals, acidity, treatment, modeling | C11: =Papers_reports!D11 -> Acid mine drainage remediation with waste products: Laboratory findings and field model applications | D11: Araújo et al. | E11: =Papers_reports!B11 -> Araújo, J.F., Cravotta, C.A. III, Fonseca, R., da Silva, R.P., Prats, A.S., Valente, T. | F11: =Papers_reports!E11 -> Proceedings 2025 International Mine Water Association Conference, Braga, Portugal, 70-76. | G11: =Papers_reports!F11 -> https://www.imwa.info/docs/imwa_2025/IMWA2025_Araujo_70.pdf
A12: =Papers_reports!C12 -> 2025 | B12: AMD, metals, acidity, treatment, modeling | C12: =Papers_reports!D12 -> Improved acidity estimation by integrating comprehensive dissolved metal(oid)s data: A geochemical modeling case study of highly mineralized mine waters | D12: Barroso et al. | E12: =Papers_reports!B12 -> Barroso, A.R., Cravotta, C.A. III, Gomes, P., Horta Ribeiro, I.M., Marinho Reis, A.P., Valente, T.M. | F12: =Papers_reports!E12 -> Proceedings 2025 International Mine Water Association Conference, Braga, Portugal, 97-101. | G12: =Papers_reports!F12 -> https://www.imwa.info/docs/imwa_2025/IMWA2025_Barroso_97.pdf
A13: =Papers_reports!C13 -> 2025 | B13: AMD, metals, acidity, treatment, modeling | C13: =Papers_reports!D13 -> Water-quality modeling tools to evaluate attenuation of dissolved constituents by precipitation and adsorption reactions during treatment of acid mine drainage | D13: Cravotta | E13: =Papers_reports!B13 -> Cravotta, C.A. III | F13: =Papers_reports!E13 -> Proceedings 2025 International Mine Water Association Conference, Braga, Portugal, 208-213. | G13: =Papers_reports!F13 -> https://www.imwa.info/docs/imwa_2025/IMWA2025_CravottaIII_208.pdf
... A44: =Papers_reports!C44 -> 2020 | B44: AMD, metals, acidity, TDS, measurement | C44: =Papers_reports!D44 -> Batch extraction method to estimate total dissolved solids (TDS) release from coal refuse and overburden | D44: Castillo-Meza et al. | E44: =Papers_reports!B44 -> Castillo-Meza, L.E., Cravotta, C.A. III, Tasker, T.L., Warner, N.R., Daniels, W.L., Orndorff, Z.W., Bergstresser, T., Douglass, A., Kimble, G., Streczywilk, J., Barton, C., Fulton, S., Thompson A., Burgos, W.D. | F44: =Papers_reports!E44 -> Applied Geochemistry 115, 104540. | G44: =Papers_reports!F44 -> https://doi.org/10.1016/j.apgeochem.2020.104540

Sheet Cravotta_biblio2026
A1: Knierim, K.J., Stackelberg, P.E., McCleskey, R.B., Cravotta, C.A. III, Belitz, K., Killian, C.D. (2026) Random forest predictions of total dissolved solids in groundwater in three dimensions across the continental United States: Water Resources Research, submitted ()
A2: Stackelberg, P.E., Knierim, K.J., Belitz, K., Cravotta, C.A. III, McCleskey, R.B., Killian, C.D. (2026) Predicting groundwater hydrochemical facies in three dimensions across the conterminous United States with random forest classification: Groundwater, submitted ()
A3: Boothe-Lordon, T.J.Cravotta, C.A. III, Tasker, T.L., Stewart, B.W., Capo, R.C., Hedin, B. (2026) Geochemical modeling of rare earth element adsorption onto aluminum hydroxide and hydroxysulfate under variable sulfate conditions: Chemosphere, submitted ()
A4: Tasker, T.L., Cravotta, C.A. III, Roman, B. (2026) Sorption of rare-earth elements with hydrous ferric oxide and hydrous aluminum oxide--Roles of sulfate and pH: Chemosphere, submitted (http://dx.doi.org/10.2139/ssrn.6208107)
A5: Roman, B., Cravotta, C.A. III, Spellman Jr., C.J., Strosnider, W.H.J., Goodwill, J.E., Tasker, T.L. (2026) Enhanced phosphorus removal via cotreatment of mine drainage during primary municipal wastewater clarification: Ecological Engineering 98 (2) e70298 (https://doi.org/10.1002/wer.70298)
A6: McCleskey, B.R., Cravotta, C.A. III, Knierim, K., Stackelberg, P.E., Killian, C. (2026) Groundwater salinity: Applying the specific conductance and water type proxy: Groundwater 64 (2) 150-160 (https://doi.org/10.1111/gwat.70038)
A7: Hayes, B., Zhu, W., Dawes, R.J., Cravotta, C.A., Hughes, R., Moyer, G., Tasker, T., Shallenberger, J., Dawes, J. (2025) Nutrient reductions as co-benefit of acid mine drainage (AMD) treatment: Quantifying nutrient load reductions for restored stream segments in AMD-impacted watersheds: Chesapeake Bay Program Scientific and Technical Advisory Committee (STAC) Publication Number 25-002, 44 p. (https://www.chesapeake.org/stac/wp-content/uploads/2025/04/STAC-Technical-Review_Acid-Mine-Drainage_25-002.pdf )
A8: McCleskey, R.B., Cravotta, C.A. III, Miller, M.P., Chapin, T.W., Tillman, F., Keith, G.L. (2025) Specific conductance and water type as a proxy model for salinity and total dissolved solids measurements in the Upper Colorado River Basin: Applied Geochemistry 184, 106358. (https://doi.org/10.1016/j.apgeochem.2025.106358 )
A9: Vesper, D.J., Cravotta, C.A. III, Lei, L., Wallace, M., Schaffer, C.R. (2025) Determination of CO2 and DIC in high-CO2 waters: An application for the analysis of coal mine waters: Applied Geochemistry 183, 106336. (https://doi.org/10.1016/j.apgeochem.2025.106336 )
A10: Araújo, J.F., Cravotta, C.A. III, Fonseca, R., da Silva, R.P., Prats, A.S., Valente, T. (2025) Acid mine drainage remediation with waste products: Laboratory findings and field model applications: Proceedings 2025 International Mine Water Association Conference, Braga, Portugal, 70-76. (https://www.imwa.info/docs/imwa_2025/IMWA2025_Araujo_70.pdf )
A11: Barroso, A.R., Cravotta, C.A. III, Gomes, P., Horta Ribeiro, I.M., Marinho Reis, A.P., Valente, T.M. (2025) Improved acidity estimation by integrating comprehensive dissolved metal(oid)s data: A geochemical modeling case study of highly mineralized mine waters: Proceedings 2025 International Mine Water Association Conference, Braga, Portugal, 97-101. (https://www.imwa.info/docs/imwa_2025/IMWA2025_Barroso_97.pdf )
A12: Cravotta, C.A. III (2025) Water-quality modeling tools to evaluate attenuation of dissolved constituents by precipitation and adsorption reactions during treatment of acid mine drainage: Proceedings 2025 International Mine Water Association Conference, Braga, Portugal, 208-213. (https://www.imwa.info/docs/imwa_2025/IMWA2025_CravottaIII_208.pdf )
... A134: Cravotta, C.A. III (1988) A mass-balance approach for interpreting the chemical composition of a conduit spring in Blair County, Pennsylvania: Proceedings Ground Water Geochemistry Conference: Dublin, Ohio, National Water Well Association, 103-126. ()

Sheet Papers_reports
A1: SORT | B1: AUTHORS | C1: YEAR | D1: TITLE | E1: PUBLICATION | F1: WEB_LINK | G1: BIBLIOGRAPHIC_CITATION
A2: =1+A3 -> 134 | B2: Knierim, K.J., Stackelberg, P.E., McCleskey, R.B., Cravotta, C.A. III, Belitz, K., Killian, C.D. | C2: 2026 | D2: Random forest predictions of total dissolved solids in groundwater in three dimensions across the continental United States | E2: Water Resources Research, submitted | G2: =CONCATENATE(B2," (",C2,") ",D2,": ",E2," (",F2,")") -> Knierim, K.J., Stackelberg, P.E., McCleskey, R.B., Cravotta, C.A. III, Belitz, K., Killian, C.D. (2026) Random forest predictions of total dissolved solids in groundwater in three dimensions across the continental United States: Water Resources Research, submitted ()
A3: =1+A4 -> 133 | B3: Stackelberg, P.E., Knierim, K.J., Belitz, K., Cravotta, C.A. III, McCleskey, R.B., Killian, C.D. | C3: 2026 | D3: Predicting groundwater hydrochemical facies in three dimensions across the conterminous United States with random forest classification | E3: Groundwater, submitted | G3: =CONCATENATE(B3," (",C3,") ",D3,": ",E3," (",F3,")") -> Stackelberg, P.E., Knierim, K.J., Belitz, K., Cravotta, C.A. III, McCleskey, R.B., Killian, C.D. (2026) Predicting groundwater hydrochemical facies in three dimensions across the conterminous United States with random forest classification: Groundwater, submitted ()
A4: =1+A5 -> 132 | B4: Boothe-Lordon, T.J.Cravotta, C.A. III, Tasker, T.L., Stewart, B.W., Capo, R.C., Hedin, B. | C4: 2026 | D4: Geochemical modeling of rare earth element adsorption onto aluminum hydroxide and hydroxysulfate under variable sulfate conditions | E4: Chemosphere, submitted | G4: =CONCATENATE(B4," (",C4,") ",D4,": ",E4," (",F4,")") -> Boothe-Lordon, T.J.Cravotta, C.A. III, Tasker, T.L., Stewart, B.W., Capo, R.C., Hedin, B. (2026) Geochemical modeling of rare earth element adsorption onto aluminum hydroxide and hydroxysulfate under variable sulfate conditions: Chemosphere, submitted ()
A5: =1+A6 -> 131 | B5: Tasker, T.L., Cravotta, C.A. III, Roman, B. | C5: 2026 | D5: Sorption of rare-earth elements with hydrous ferric oxide and hydrous aluminum oxide--Roles of sulfate and pH | E5: Chemosphere, submitted | F5: http://dx.doi.org/10.2139/ssrn.6208107 | G5: =CONCATENATE(B5," (",C5,") ",D5,": ",E5," (",F5,")") -> Tasker, T.L., Cravotta, C.A. III, Roman, B. (2026) Sorption of rare-earth elements with hydrous ferric oxide and hydrous aluminum oxide--Roles of sulfate and pH: Chemosphere, submitted (http://dx.doi.org/10.2139/ssrn.6208107)
A6: =1+A7 -> 130 | B6: Roman, B., Cravotta, C.A. III, Spellman Jr., C.J., Strosnider, W.H.J., Goodwill, J.E., Tasker, T.L. | C6: 2026 | D6: Enhanced phosphorus removal via cotreatment of mine drainage during primary municipal wastewater clarification | E6: Ecological Engineering 98 (2) e70298 | F6: https://doi.org/10.1002/wer.70298 | G6: =CONCATENATE(B6," (",C6,") ",D6,": ",E6," (",F6,")") -> Roman, B., Cravotta, C.A. III, Spellman Jr., C.J., Strosnider, W.H.J., Goodwill, J.E., Tasker, T.L. (2026) Enhanced phosphorus removal via cotreatment of mine drainage during primary municipal wastewater clarification: Ecological Engineering 98 (2) e70298 (https://doi.org/10.1002/wer.70298)
A7: =1+A8 -> 129 | B7: McCleskey, B.R., Cravotta, C.A. III, Knierim, K., Stackelberg, P.E., Killian, C. | C7: 2026 | D7: Groundwater salinity: Applying the specific conductance and water type proxy | E7: Groundwater 64 (2) 150-160 | F7: https://doi.org/10.1111/gwat.70038 | G7: =CONCATENATE(B7," (",C7,") ",D7,": ",E7," (",F7,")") -> McCleskey, B.R., Cravotta, C.A. III, Knierim, K., Stackelberg, P.E., Killian, C. (2026) Groundwater salinity: Applying the specific conductance and water type proxy: Groundwater 64 (2) 150-160 (https://doi.org/10.1111/gwat.70038)
A8: =1+A9 -> 128 | B8: Hayes, B., Zhu, W., Dawes, R.J., Cravotta, C.A., Hughes, R., Moyer, G., Tasker, T., Shallenberger, J., Dawes, J. | C8: 2025 | D8: Nutrient reductions as co-benefit of acid mine drainage (AMD) treatment: Quantifying nutrient load reductions for restored stream segments in AMD-impacted watersheds | E8: Chesapeake Bay Program Scientific and Technical Advisory Committee (STAC) Publication Number 25-002, 44 p. | F8: https://www.chesapeake.org/stac/wp-content/uploads/2025/04/STAC-Technical-Review_Acid-Mine-Drainage_25-002.pdf | G8: =CONCATENATE(B8," (",C8,") ",D8,": ",E8," (",F8,")") -> Hayes, B., Zhu, W., Dawes, R.J., Cravotta, C.A., Hughes, R., Moyer, G., Tasker, T., Shallenberger, J., Dawes, J. (2025) Nutrient reductions as co-benefit of acid mine drainage (AMD) treatment: Quantifying nutrient load reductions for restored stream segments in AMD-impacted watersheds: Chesapeake Bay Program Scientific and Technical Advisory Committee (STAC) Publication Number 25-002, 44 p. (https://www.chesapeake.org/stac/wp-content/uploads/2025/04/STAC-Technical-Review_Acid-Mine-Drainage_25-002.pdf )
A9: =1+A10 -> 127 | B9: McCleskey, R.B., Cravotta, C.A. III, Miller, M.P., Chapin, T.W., Tillman, F., Keith, G.L. | C9: 2025 | D9: Specific conductance and water type as a proxy model for salinity and total dissolved solids measurements in the Upper Colorado River Basin | E9: Applied Geochemistry 184, 106358. | F9: https://doi.org/10.1016/j.apgeochem.2025.106358 | G9: =CONCATENATE(B9," (",C9,") ",D9,": ",E9," (",F9,")") -> McCleskey, R.B., Cravotta, C.A. III, Miller, M.P., Chapin, T.W., Tillman, F., Keith, G.L. (2025) Specific conductance and water type as a proxy model for salinity and total dissolved solids measurements in the Upper Colorado River Basin: Applied Geochemistry 184, 106358. (https://doi.org/10.1016/j.apgeochem.2025.106358 )
A10: =1+A11 -> 126 | B10: Vesper, D.J., Cravotta, C.A. III, Lei, L., Wallace, M., Schaffer, C.R. | C10: 2025 | D10: Determination of CO2 and DIC in high-CO2 waters: An application for the analysis of coal mine waters | E10: Applied Geochemistry 183, 106336. | F10: https://doi.org/10.1016/j.apgeochem.2025.106336 | G10: =CONCATENATE(B10," (",C10,") ",D10,": ",E10," (",F10,")") -> Vesper, D.J., Cravotta, C.A. III, Lei, L., Wallace, M., Schaffer, C.R. (2025) Determination of CO2 and DIC in high-CO2 waters: An application for the analysis of coal mine waters: Applied Geochemistry 183, 106336. (https://doi.org/10.1016/j.apgeochem.2025.106336 )
A11: =1+A12 -> 125 | B11: Araújo, J.F., Cravotta, C.A. III, Fonseca, R., da Silva, R.P., Prats, A.S., Valente, T. | C11: 2025 | D11: Acid mine drainage remediation with waste products: Laboratory findings and field model applications | E11: Proceedings 2025 International Mine Water Association Conference, Braga, Portugal, 70-76. | F11: https://www.imwa.info/docs/imwa_2025/IMWA2025_Araujo_70.pdf | G11: =CONCATENATE(B11," (",C11,") ",D11,": ",E11," (",F11,")") -> Araújo, J.F., Cravotta, C.A. III, Fonseca, R., da Silva, R.P., Prats, A.S., Valente, T. (2025) Acid mine drainage remediation with waste products: Laboratory findings and field model applications: Proceedings 2025 International Mine Water Association Conference, Braga, Portugal, 70-76. (https://www.imwa.info/docs/imwa_2025/IMWA2025_Araujo_70.pdf )
A12: =1+A13 -> 124 | B12: Barroso, A.R., Cravotta, C.A. III, Gomes, P., Horta Ribeiro, I.M., Marinho Reis, A.P., Valente, T.M. | C12: 2025 | D12: Improved acidity estimation by integrating comprehensive dissolved metal(oid)s data: A geochemical modeling case study of highly mineralized mine waters | E12: Proceedings 2025 International Mine Water Association Conference, Braga, Portugal, 97-101. | F12: https://www.imwa.info/docs/imwa_2025/IMWA2025_Barroso_97.pdf | G12: =CONCATENATE(B12," (",C12,") ",D12,": ",E12," (",F12,")") -> Barroso, A.R., Cravotta, C.A. III, Gomes, P., Horta Ribeiro, I.M., Marinho Reis, A.P., Valente, T.M. (2025) Improved acidity estimation by integrating comprehensive dissolved metal(oid)s data: A geochemical modeling case study of highly mineralized mine waters: Proceedings 2025 International Mine Water Association Conference, Braga, Portugal, 97-101. (https://www.imwa.info/docs/imwa_2025/IMWA2025_Barroso_97.pdf )
A13: =1+A14 -> 123 | B13: Cravotta, C.A. III | C13: 2025 | D13: Water-quality modeling tools to evaluate attenuation of dissolved constituents by precipitation and adsorption reactions during treatment of acid mine drainage | E13: Proceedings 2025 International Mine Water Association Conference, Braga, Portugal, 208-213. | F13: https://www.imwa.info/docs/imwa_2025/IMWA2025_CravottaIII_208.pdf | G13: =CONCATENATE(B13," (",C13,") ",D13,": ",E13," (",F13,")") -> Cravotta, C.A. III (2025) Water-quality modeling tools to evaluate attenuation of dissolved constituents by precipitation and adsorption reactions during treatment of acid mine drainage: Proceedings 2025 International Mine Water Association Conference, Braga, Portugal, 208-213. (https://www.imwa.info/docs/imwa_2025/IMWA2025_CravottaIII_208.pdf )
A14: =1+A15 -> 122 | B14: McDevitt, B., Cravotta, C.A. III, McAleer, R.J., Jackson, J.C., Jubb, A.M., Jolly, G.D., Hedin, B.C., Warner, N.R. | C14: 2024 | D14: Evaluation of coal mine drainage and associated precipitates for radium and rare earth element concentrations | E14: International Journal of Coal Geology 28, 104547. | F14: https://doi.org/10.1016/j.coal.2024.104547 | G14: =CONCATENATE(B14," (",C14,") ",D14,": ",E14," (",F14,")") -> McDevitt, B., Cravotta, C.A. III, McAleer, R.J., Jackson, J.C., Jubb, A.M., Jolly, G.D., Hedin, B.C., Warner, N.R. (2024) Evaluation of coal mine drainage and associated precipitates for radium and rare earth element concentrations: International Journal of Coal Geology 28, 104547. (https://doi.org/10.1016/j.coal.2024.104547)
A15: =1+A16 -> 121 | B15: Cravotta, C.A. III | C15: 2024 | D15: Geochemical modeling to understand and mitigate aquatic contamination by abandoned mine drainage | E15: Proceedings of the West Virginia Mine Drainage Task Force Symposium & 15th International Mine Water Association Congress, Morgantown, WV, USA, 91-97. | F15: https://www.imwa.info/docs/imwa_2024/IMWA2024_CravottaIII_91.pdf | G15: =CONCATENATE(B15," (",C15,") ",D15,": ",E15," (",F15,")") -> Cravotta, C.A. III (2024) Geochemical modeling to understand and mitigate aquatic contamination by abandoned mine drainage: Proceedings of the West Virginia Mine Drainage Task Force Symposium & 15th International Mine Water Association Congress, Morgantown, WV, USA, 91-97. (https://www.imwa.info/docs/imwa_2024/IMWA2024_CravottaIII_91.pdf)
A16: =1+A17 -> 120 | B16: Cravotta, C.A. III, Tasker, T.L., Hedin, B.C. | C16: 2024 | D16: Laboratory and field observations inform geochemical models of treatment strategies to recover rare-earth elements from acid mine drainage | E16: Proceedings of the West Virginia Mine Drainage Task Force Symposium & 15th International Mine Water Association Congress, Morgantown, WV, USA, 98-104. | F16: https://www.imwa.info/docs/imwa_2024/IMWA2024_CravottaIII_98.pdf | G16: =CONCATENATE(B16," (",C16,") ",D16,": ",E16," (",F16,")") -> Cravotta, C.A. III, Tasker, T.L., Hedin, B.C. (2024) Laboratory and field observations inform geochemical models of treatment strategies to recover rare-earth elements from acid mine drainage: Proceedings of the West Virginia Mine Drainage Task Force Symposium & 15th International Mine Water Association Congress, Morgantown, WV, USA, 98-104. (https://www.imwa.info/docs/imwa_2024/IMWA2024_CravottaIII_98.pdf)
... A19: =1+A20 -> 117 | B19: Cravotta, C.A. III | C19: 2024 | D19: Interactive PHREEQ-N-Ra-Cl-pH-Titration water-quality modeling tools to evaluate potential aqueous/solid equilibrium distributions of radium and associated dissolved constituents in response to changes in salinity or pH (software download) | E19: : U.S. Geological Survey Software Release. | F19: https://doi.org/10.5066/P9157D7U | G19: =CONCATENATE(B19," (",C19,") ",D19,": ",E19," (",F19,")") -> Cravotta, C.A. III (2024) Interactive PHREEQ-N-Ra-Cl-pH-Titration water-quality modeling tools to evaluate potential aqueous/solid equilibrium distributions of radium and associated dissolved constituents in response to changes in salinity or pH (software download): : U.S. Geological Survey Software Release. (https://doi.org/10.5066/P9157D7U)
A20: 116 | B20: Schaffer, C.R., Cravotta, C.A. III, Capo, R.C., Hedin, B.C., Vesper, D.J., Stewart, B.W. | C20: 2024 | D20: Multi-decadal geochemical evolution of drainage from underground coal mines in the Appalachian basin, USA | E20: Science of the Total Environment 947, 174681. | F20: https://doi.org/10.1016/j.scitotenv.2024.174681 | G20: =CONCATENATE(B20," (",C20,") ",D20,": ",E20," (",F20,")") -> Schaffer, C.R., Cravotta, C.A. III, Capo, R.C., Hedin, B.C., Vesper, D.J., Stewart, B.W. (2024) Multi-decadal geochemical evolution of drainage from underground coal mines in the Appalachian basin, USA: Science of the Total Environment 947, 174681. (https://doi.org/10.1016/j.scitotenv.2024.174681)
A21: 115 | B21: Marks, N.J., Cravotta, C.A. III, Rossi, M.L., Silva, C., Kremer, P., Goldsmith, S. | C21: 2024 | D21: Exploring spatial and temporal symptoms of the freshwater salinization syndrome in a rural to urban watershed | E21: Science of the Total Environment 947, 174266. | F21: https://doi.org/10.1016/j.scitotenv.2024.174266 | G21: =CONCATENATE(B21," (",C21,") ",D21,": ",E21," (",F21,")") -> Marks, N.J., Cravotta, C.A. III, Rossi, M.L., Silva, C., Kremer, P., Goldsmith, S. (2024) Exploring spatial and temporal symptoms of the freshwater salinization syndrome in a rural to urban watershed: Science of the Total Environment 947, 174266. (https://doi.org/10.1016/j.scitotenv.2024.174266)
A22: 114 | B22: Clune, J.W., Cravotta, C.A. III, Husic, A., Dozier, H.J., Schimdt, K.E. | C22: 2024 | D22: Complex hydrology and variability of nitrogen sources in a karst watershed | E22: Journal of Environmental Quality 53, 492-507. | F22: https://doi.org/10.1002/jeq2.20578 | G22: =CONCATENATE(B22," (",C22,") ",D22,": ",E22," (",F22,")") -> Clune, J.W., Cravotta, C.A. III, Husic, A., Dozier, H.J., Schimdt, K.E. (2024) Complex hydrology and variability of nitrogen sources in a karst watershed: Journal of Environmental Quality 53, 492-507. (https://doi.org/10.1002/jeq2.20578)
A23: =1+A24 -> 113 | B23: Cravotta, C.A. III, Tasker, T.L., Smyntek, P.M., Blomquist, J.D., Clune, J.W., Zhang, Q., Schmadel, N.M., Schmer, N.K. | C23: 2024 | D23: Legacy sediment as a potential source of orthophosphate: Preliminary conceptual and geochemical models for the Susquehanna River, Chesapeake Bay Watershed, USA | E23: Science of the Total Environment 912, 169361. | F23: https://doi.org/10.1016/j.scitotenv.2023.169361 | G23: =CONCATENATE(B23," (",C23,") ",D23,": ",E23," (",F23,")") -> Cravotta, C.A. III, Tasker, T.L., Smyntek, P.M., Blomquist, J.D., Clune, J.W., Zhang, Q., Schmadel, N.M., Schmer, N.K. (2024) Legacy sediment as a potential source of orthophosphate: Preliminary conceptual and geochemical models for the Susquehanna River, Chesapeake Bay Watershed, USA: Science of the Total Environment 912, 169361. (https://doi.org/10.1016/j.scitotenv.2023.169361)
A24: =1+A25 -> 112 | B24: Hedin, B.C., Stuckman, M.Y., Cravotta C.A. III, Lopano, C.L., Capo, R.C. | C24: 2024 | D24: Determination and prediction of micro scale rare earth element geochemical associations in mine drainage treatment wastes | E24: Chemosphere 346, 147475. | F24: https://doi.org/10.1016/j.chemosphere.2023.140475 | G24: =CONCATENATE(B24," (",C24,") ",D24,": ",E24," (",F24,")") -> Hedin, B.C., Stuckman, M.Y., Cravotta C.A. III, Lopano, C.L., Capo, R.C. (2024) Determination and prediction of micro scale rare earth element geochemical associations in mine drainage treatment wastes: Chemosphere 346, 147475. (https://doi.org/10.1016/j.chemosphere.2023.140475)
A25: =1+A26 -> 111 | B25: Rossi, M.L., Kremer, P., Cravotta, C.A., Seng, K.E., Goldsmith, S.T. | C25: 2023 | D25: Land development and road salt usage drive long-term changes in major-ion chemistry of streamwater in six exurban and suburban watersheds, southeastern Pennsylvania, 1999–2019 | E25: Frontiers in Environmental Science 11, 1153133. | F25: https://doi.org/10.3389/fenvs.2023.1153133 | G25: =CONCATENATE(B25," (",C25,") ",D25,": ",E25," (",F25,")") -> Rossi, M.L., Kremer, P., Cravotta, C.A., Seng, K.E., Goldsmith, S.T. (2023) Land development and road salt usage drive long-term changes in major-ion chemistry of streamwater in six exurban and suburban watersheds, southeastern Pennsylvania, 1999–2019: Frontiers in Environmental Science 11, 1153133. (https://doi.org/10.3389/fenvs.2023.1153133)
A26: =1+A27 -> 110 | B26: McCleskey, R.B., Cravotta C.A. III, Miller, M.P., Tillman, F., Stackelberg, P., Knierim, K.J., Wise, D.R. | C26: 2023 | D26: Salinity and total dissolved solids measurements for natural waters: an overview and a new salinity estimation method based on specific conductance measurements and water ty | E26: Applied Geochemistry 154 105684. | F26: https://doi.org/10.1016/j.apgeochem.2023.105684 | G26: =CONCATENATE(B26," (",C26,") ",D26,": ",E26," (",F26,")") -> McCleskey, R.B., Cravotta C.A. III, Miller, M.P., Tillman, F., Stackelberg, P., Knierim, K.J., Wise, D.R. (2023) Salinity and total dissolved solids measurements for natural waters: an overview and a new salinity estimation method based on specific conductance measurements and water ty: Applied Geochemistry 154 105684. (https://doi.org/10.1016/j.apgeochem.2023.105684)
A27: 109 | B27: Szabo, Z., Cravotta, C.A. III, Stackelberg, P.E., Belitz, K. | C27: 2023 | D27: Gross alpha-particle activity regulation might not be protective for 210Po in the Atlantic and Gulf Coastal Plain aquifers of the United States | E27: ES&T Water 3, 262-274. | F27: https://doi.org/10.1021/acsestwater.2c00027 | G27: =CONCATENATE(B27," (",C27,") ",D27,": ",E27," (",F27,")") -> Szabo, Z., Cravotta, C.A. III, Stackelberg, P.E., Belitz, K. (2023) Gross alpha-particle activity regulation might not be protective for 210Po in the Atlantic and Gulf Coastal Plain aquifers of the United States: ES&T Water 3, 262-274. (https://doi.org/10.1021/acsestwater.2c00027)
A28: 108 | B28: Cravotta, C.A. III | C28: 2022 | D28: PHREEQ-N-AMDTreat+REYS water-quality modeling tools to evaluate acid mine drainage treatment strategies for recovery of rare-earth elements | E28: Proceedings of the 12th International Conference on Acid Mine Drainage, online. 18-24 September 2022, 788-804. | F28: https://drive.google.com/file/d/1H07fhUBKaqLFTQl5DwYH-bxOHWctIdbJ/view | G28: =CONCATENATE(B28," (",C28,") ",D28,": ",E28," (",F28,")") -> Cravotta, C.A. III (2022) PHREEQ-N-AMDTreat+REYS water-quality modeling tools to evaluate acid mine drainage treatment strategies for recovery of rare-earth elements: Proceedings of the 12th International Conference on Acid Mine Drainage, online. 18-24 September 2022, 788-804. (https://drive.google.com/file/d/1H07fhUBKaqLFTQl5DwYH-bxOHWctIdbJ/view)
A29: 107 | B29: Hedin, B.C., Cravotta, C.A., Stuckman, M.Y., Lopano, C.L., Capo, R.C., Hedin, R.S. | C29: 2022 | D29: Determination and prediction of rare earth element geochemical associations in acid mine drainage treatment wastes | E29: Proceedings of the 12th International Conference on Acid Mine Drainage, online. 18-24 September 2022, 626-633. | F29: https://drive.google.com/file/d/1H07fhUBKaqLFTQl5DwYH-bxOHWctIdbJ/view | G29: =CONCATENATE(B29," (",C29,") ",D29,": ",E29," (",F29,")") -> Hedin, B.C., Cravotta, C.A., Stuckman, M.Y., Lopano, C.L., Capo, R.C., Hedin, R.S. (2022) Determination and prediction of rare earth element geochemical associations in acid mine drainage treatment wastes: Proceedings of the 12th International Conference on Acid Mine Drainage, online. 18-24 September 2022, 626-633. (https://drive.google.com/file/d/1H07fhUBKaqLFTQl5DwYH-bxOHWctIdbJ/view)
A30: =1+A31 -> 106 | B30: Rossi, M.L., Kremer, Peleg, Cravotta, C.A., Scheirer, K.E., Goldsmith, S.T. | C30: 2022 | D30: Long-term impacts of impervious surface cover change and roadway deicing agent application on chloride concentrations in exurban and suburban watersheds | E30: Science of the Total Environment 851, 157933. | F30: https://doi.org/10.1016/j.scitotenv.2022.157933 | G30: =CONCATENATE(B30," (",C30,") ",D30,": ",E30," (",F30,")") -> Rossi, M.L., Kremer, Peleg, Cravotta, C.A., Scheirer, K.E., Goldsmith, S.T. (2022) Long-term impacts of impervious surface cover change and roadway deicing agent application on chloride concentrations in exurban and suburban watersheds: Science of the Total Environment 851, 157933. (https://doi.org/10.1016/j.scitotenv.2022.157933)
A31: =1+A32 -> 105 | B31: Cravotta, C.A. III | C31: 2022 | D31: Interactive PHREEQ-N-AMDTreat+REYs water-quality modeling tools to evaluate potential attenuation of rare-earth elements and associated dissolved constituents by aqueous-solid equilibrium processes (software download) | E31: U.S. Geological Survey Software Release. | F31: https://doi.org/10.5066/P9M5QVK0 | G31: =CONCATENATE(B31," (",C31,") ",D31,": ",E31," (",F31,")") -> Cravotta, C.A. III (2022) Interactive PHREEQ-N-AMDTreat+REYs water-quality modeling tools to evaluate potential attenuation of rare-earth elements and associated dissolved constituents by aqueous-solid equilibrium processes (software download): U.S. Geological Survey Software Release. (https://doi.org/10.5066/P9M5QVK0)
A32: =1+A33 -> 104 | B32: Spellman, C.J. Jr., Smyntek, P.M., Cravotta, C.A. III, Tasker, T.L., Strosnider, W.H.J. | C32: 2022 | D32: Pollutant co-attenuation via in-stream interactions between mine drainage and municipal wastewater | E32: Water Research 214, 118173. | F32: https://doi.org/10.1016/j.watres.2022.118173 | G32: =CONCATENATE(B32," (",C32,") ",D32,": ",E32," (",F32,")") -> Spellman, C.J. Jr., Smyntek, P.M., Cravotta, C.A. III, Tasker, T.L., Strosnider, W.H.J. (2022) Pollutant co-attenuation via in-stream interactions between mine drainage and municipal wastewater: Water Research 214, 118173. (https://doi.org/10.1016/j.watres.2022.118173)
A33: =1+A34 -> 103 | B33: Smyntek, P., Lamagna, N., Cravotta, C.A. III, Strosnider, W.H.J. | C33: 2022 | D33: Mine drainage precipitates attenuate and conceal wastewater-derived phosphate pollution in stream water | E33: Science of the Total Environment 815, 152672. | F33: http://dx.doi.org/10.1016/j.scitotenv.2021.152672 | G33: =CONCATENATE(B33," (",C33,") ",D33,": ",E33," (",F33,")") -> Smyntek, P., Lamagna, N., Cravotta, C.A. III, Strosnider, W.H.J. (2022) Mine drainage precipitates attenuate and conceal wastewater-derived phosphate pollution in stream water: Science of the Total Environment 815, 152672. (http://dx.doi.org/10.1016/j.scitotenv.2021.152672)
A34: =1+A35 -> 102 | B34: Cravotta, C.A. III, Senior, L.A., Conlon, M.D. | C34: 2022 | D34: Factors affecting groundwater quality used for domestic supply in Marcellus Shale region of north-central and north-east Pennsylvania, USA | E34: Applied Geochemistry 137, 105149. | F34: https://doi.org/10.1016/j.apgeochem.2021.105149 | G34: =CONCATENATE(B34," (",C34,") ",D34,": ",E34," (",F34,")") -> Cravotta, C.A. III, Senior, L.A., Conlon, M.D. (2022) Factors affecting groundwater quality used for domestic supply in Marcellus Shale region of north-central and north-east Pennsylvania, USA: Applied Geochemistry 137, 105149. (https://doi.org/10.1016/j.apgeochem.2021.105149)
A35: =1+A36 -> 101 | B35: Lindsey, B.D., Cravotta, C.A. III, Szabo, Z., Belitz, K., Stackelberg, P.E. | C35: 2021 | D35: Relation between road-salt application and increasing radium concentrations in a low-pH aquifer, southern New Jersey | E35: ES&T Water 1, 2541-2547. | F35: https://doi.org/10.1021/acsestwater.1c00307 | G35: =CONCATENATE(B35," (",C35,") ",D35,": ",E35," (",F35,")") -> Lindsey, B.D., Cravotta, C.A. III, Szabo, Z., Belitz, K., Stackelberg, P.E. (2021) Relation between road-salt application and increasing radium concentrations in a low-pH aquifer, southern New Jersey: ES&T Water 1, 2541-2547. (https://doi.org/10.1021/acsestwater.1c00307)
A36: =1+A37 -> 100 | B36: Cravotta, C.A. III | C36: 2021 | D36: Interactive PHREEQ-N-Titration-PO4-Adsorption water-quality modeling tools to evaluate potential attenuation of phosphate and associated dissolved constituents by aqueous-solid equilibrium processes (software download) | E36: U.S. Geological Survey Software Release. | F36: https://doi.org/10.5066/P9D8VQDV | G36: =CONCATENATE(B36," (",C36,") ",D36,": ",E36," (",F36,")") -> Cravotta, C.A. III (2021) Interactive PHREEQ-N-Titration-PO4-Adsorption water-quality modeling tools to evaluate potential attenuation of phosphate and associated dissolved constituents by aqueous-solid equilibrium processes (software download): U.S. Geological Survey Software Release. (https://doi.org/10.5066/P9D8VQDV)
A37: =1+A38 -> 99 | B37: Erickson, M.L., Elliott, S.M., Brown, C.J., Stackelberg, P.E., Ransom, K.M., Reddy, J.E., Cravotta, C.A. III | C37: 2021 | D37: Machine-learning predictions of high arsenic and high manganese at drinking water depths of the Glacial Aquifer System, northern continental United States | E37: Environmental Science & Technology 55, 5791-5805. | F37: https://doi.org/10.1021/acs.est.0c06740 | G37: =CONCATENATE(B37," (",C37,") ",D37,": ",E37," (",F37,")") -> Erickson, M.L., Elliott, S.M., Brown, C.J., Stackelberg, P.E., Ransom, K.M., Reddy, J.E., Cravotta, C.A. III (2021) Machine-learning predictions of high arsenic and high manganese at drinking water depths of the Glacial Aquifer System, northern continental United States: Environmental Science & Technology 55, 5791-5805. (https://doi.org/10.1021/acs.est.0c06740)
A38: =1+A39 -> 98 | B38: Cravotta, C.A. III | C38: 2021 | D38: Interactive PHREEQ-N-AMDTreat water-quality modeling tools to evaluate performance and design of treatment systems for acid mine drainage | E38: Applied Geochemistry 126, 10845. | F38: https://doi.org/10.1016/j.apgeochem.2020.104845 | G38: =CONCATENATE(B38," (",C38,") ",D38,": ",E38," (",F38,")") -> Cravotta, C.A. III (2021) Interactive PHREEQ-N-AMDTreat water-quality modeling tools to evaluate performance and design of treatment systems for acid mine drainage: Applied Geochemistry 126, 10845. (https://doi.org/10.1016/j.apgeochem.2020.104845)
A39: =1+A40 -> 97 | B39: Lindsey, B.D., Belitz, Kenneth, Cravotta, C.A. III, Dubrovsky, N.M., Toccalino, Patricia | C39: 2021 | D39: Lithium in groundwater used for drinking-water supply in the United States | E39: Science of the Total Environment 767, 144691. | F39: https://doi.org/10.1016/j.scitotenv.2020.144691 | G39: =CONCATENATE(B39," (",C39,") ",D39,": ",E39," (",F39,")") -> Lindsey, B.D., Belitz, Kenneth, Cravotta, C.A. III, Dubrovsky, N.M., Toccalino, Patricia (2021) Lithium in groundwater used for drinking-water supply in the United States: Science of the Total Environment 767, 144691. (https://doi.org/10.1016/j.scitotenv.2020.144691)
A40: =1+A41 -> 96 | B40: Cravotta, C.A. III | C40: 2020 | D40: Interactive PHREEQ-N-AMDTreat water-quality modeling tools to evaluate performance and design of treatment systems for acid mine drainage (software download) | E40: U.S. Geological Survey Software Release. | F40: https://doi.org/10.5066/P9QEE3D5 | G40: =CONCATENATE(B40," (",C40,") ",D40,": ",E40," (",F40,")") -> Cravotta, C.A. III (2020) Interactive PHREEQ-N-AMDTreat water-quality modeling tools to evaluate performance and design of treatment systems for acid mine drainage (software download): U.S. Geological Survey Software Release. (https://doi.org/10.5066/P9QEE3D5)
A41: =1+A42 -> 95 | B41: Galeone, D.G., Cravotta, C.A. III, Risser, D.W. | C41: 2020 | D41: Groundwater quality in relation to drinking water health standards and hydrogeologic and geochemical characteristics for 47 domestic wells in Potter County, Pennsylvania, 2017 | E41: U.S. Geological Survey Scientific Investigations Report 2020-5038, 67 p. | F41: https://doi.org/10.3133/sir20205038 | G41: =CONCATENATE(B41," (",C41,") ",D41,": ",E41," (",F41,")") -> Galeone, D.G., Cravotta, C.A. III, Risser, D.W. (2020) Groundwater quality in relation to drinking water health standards and hydrogeologic and geochemical characteristics for 47 domestic wells in Potter County, Pennsylvania, 2017: U.S. Geological Survey Scientific Investigations Report 2020-5038, 67 p. (https://doi.org/10.3133/sir20205038)
... A110: =1+A111 -> 26 | B110: Cravotta, C.A. III, Hilgar, G.M. | C110: 2000 | D110: Considerations for chemical monitoring at coal mines | E110: Acid Drainage Technology Initiative, Morgantown, W.V., National Mine Land Reclamation Center, 195-218. | F110: http://www.techtransfer.osmre.gov/NTTMainSite/Library/hbmanual/predictH2O/appendixA.pdf | G110: =CONCATENATE(B110," (",C110,") ",D110,": ",E110," (",F110,")") -> Cravotta, C.A. III, Hilgar, G.M. (2000) Considerations for chemical monitoring at coal mines: Acid Drainage Technology Initiative, Morgantown, W.V., National Mine Land Reclamation Center, 195-218. (http://www.techtransfer.osmre.gov/NTTMainSite/Library/hbmanual/predictH2O/appendixA.pdf)
...
